2025-09-01 02:26:34,702 - __main__ - INFO - ðŸš€ Ø¨Ø¯Ø¡ ØªØ´ØºÙŠÙ„ Ø§Ù„Ø¨ÙˆØª...
2025-09-01 02:26:34,916 - __main__ - INFO - âœ… Ø§Ù„Ø¨ÙˆØª Ø¬Ø§Ù‡Ø²! Token: 7958170099:AAHsSsdd4...
2025-09-01 02:26:35,360 - httpx - INFO - HTTP Request: POST https://api.telegram.org/bot7958170099:AAHsSsdd4WiE1MkZMSUQlm0QpzDYDL-rN5Y/getMe "HTTP/1.1 200 OK"
2025-09-01 02:26:35,508 - httpx - INFO - HTTP Request: POST https://api.telegram.org/bot7958170099:AAHsSsdd4WiE1MkZMSUQlm0QpzDYDL-rN5Y/deleteWebhook "HTTP/1.1 200 OK"
2025-09-01 02:26:35,510 - telegram.ext.Application - INFO - Application started
2025-09-01 02:26:40,046 - httpx - INFO - HTTP Request: POST https://api.telegram.org/bot7958170099:AAHsSsdd4WiE1MkZMSUQlm0QpzDYDL-rN5Y/getUpdates "HTTP/1.1 409 Conflict"
2025-09-01 02:26:40,047 - telegram.ext.Application - ERROR - No error handlers are registered, logging exception.
Traceback (most recent call last):
  File "/usr/local/lib/python3.12/site-packages/telegram/ext/_utils/networkloop.py", line 115, in network_retry_loop
    if not await do_action():
           ^^^^^^^^^^^^^^^^^
  File "/usr/local/lib/python3.12/site-packages/telegram/ext/_utils/networkloop.py", line 108, in do_action
    return action_cb_task.result()
           ^^^^^^^^^^^^^^^^^^^^^^^
  File "/usr/local/lib/python3.12/site-packages/telegram/ext/_updater.py", line 340, in polling_action_cb
    updates = await self.bot.get_updates(
              ^^^^^^^^^^^^^^^^^^^^^^^^^^^
  File "/usr/local/lib/python3.12/site-packages/telegram/ext/_extbot.py", line 670, in get_updates
    updates = await super().get_updates(
              ^^^^^^^^^^^^^^^^^^^^^^^^^^
  File "/usr/local/lib/python3.12/site-packages/telegram/_bot.py", line 4611, in get_updates
    await self._post(
  File "/usr/local/lib/python3.12/site-packages/telegram/_bot.py", line 698, in _post
    return await self._do_post(
           ^^^^^^^^^^^^^^^^^^^^
  File "/usr/local/lib/python3.12/site-packages/telegram/ext/_extbot.py", line 370, in _do_post
    return await super()._do_post(
           ^^^^^^^^^^^^^^^^^^^^^^^
  File "/usr/local/lib/python3.12/site-packages/telegram/_bot.py", line 727, in _do_post
    result = await request.post(
             ^^^^^^^^^^^^^^^^^^^
  File "/usr/local/lib/python3.12/site-packages/telegram/request/_baserequest.py", line 197, in post
    result = await self._request_wrapper(
             ^^^^^^^^^^^^^^^^^^^^^^^^^^^^
  File "/usr/local/lib/python3.12/site-packages/telegram/request/_baserequest.py", line 374, in _request_wrapper
    raise exception
telegram.error.Conflict: Conflict: terminated by other getUpdates request; make sure that only one bot instance is running
2025-09-01 02:26:45,833 - httpx - INFO - HTTP Request: POST https://api.telegram.org/bot7958170099:AAHsSsdd4WiE1MkZMSUQlm0QpzDYDL-rN5Y/getUpdates "HTTP/1.1 409 Conflict"
2025-09-01 02:26:45,834 - telegram.ext.Application - ERROR - No error handlers are registered, logging exception.
Traceback (most recent call last):
  File "/usr/local/lib/python3.12/site-packages/telegram/ext/_utils/networkloop.py", line 115, in network_retry_loop
    if not await do_action():
           ^^^^^^^^^^^^^^^^^
  File "/usr/local/lib/python3.12/site-packages/telegram/ext/_utils/networkloop.py", line 108, in do_action
    return action_cb_task.result()
           ^^^^^^^^^^^^^^^^^^^^^^^
  File "/usr/local/lib/python3.12/site-packages/telegram/ext/_updater.py", line 340, in polling_action_cb
    updates = await self.bot.get_updates(
              ^^^^^^^^^^^^^^^^^^^^^^^^^^^
  File "/usr/local/lib/python3.12/site-packages/telegram/ext/_extbot.py", line 670, in get_updates
    updates = await super().get_updates(
              ^^^^^^^^^^^^^^^^^^^^^^^^^^
  File "/usr/local/lib/python3.12/site-packages/telegram/_bot.py", line 4611, in get_updates
    await self._post(
  File "/usr/local/lib/python3.12/site-packages/telegram/_bot.py", line 698, in _post
    return await self._do_post(
           ^^^^^^^^^^^^^^^^^^^^
  File "/usr/local/lib/python3.12/site-packages/telegram/ext/_extbot.py", line 370, in _do_post
    return await super()._do_post(
           ^^^^^^^^^^^^^^^^^^^^^^^
  File "/usr/local/lib/python3.12/site-packages/telegram/_bot.py", line 727, in _do_post
    result = await request.post(
             ^^^^^^^^^^^^^^^^^^^
  File "/usr/local/lib/python3.12/site-packages/telegram/request/_baserequest.py", line 197, in post
    result = await self._request_wrapper(
             ^^^^^^^^^^^^^^^^^^^^^^^^^^^^
  File "/usr/local/lib/python3.12/site-packages/telegram/request/_baserequest.py", line 374, in _request_wrapper
    raise exception
telegram.error.Conflict: Conflict: terminated by other getUpdates request; make sure that only one bot instance is running
2025-09-01 02:26:52,861 - httpx - INFO - HTTP Request: POST https://api.telegram.org/bot7958170099:AAHsSsdd4WiE1MkZMSUQlm0QpzDYDL-rN5Y/getUpdates "HTTP/1.1 409 Conflict"
2025-09-01 02:26:52,862 - telegram.ext.Application - ERROR - No error handlers are registered, logging exception.
Traceback (most recent call last):
  File "/usr/local/lib/python3.12/site-packages/telegram/ext/_utils/networkloop.py", line 115, in network_retry_loop
    if not await do_action():
           ^^^^^^^^^^^^^^^^^
  File "/usr/local/lib/python3.12/site-packages/telegram/ext/_utils/networkloop.py", line 108, in do_action
    return action_cb_task.result()
           ^^^^^^^^^^^^^^^^^^^^^^^
  File "/usr/local/lib/python3.12/site-packages/telegram/ext/_updater.py", line 340, in polling_action_cb
    updates = await self.bot.get_updates(
              ^^^^^^^^^^^^^^^^^^^^^^^^^^^
  File "/usr/local/lib/python3.12/site-packages/telegram/ext/_extbot.py", line 670, in get_updates
    updates = await super().get_updates(
              ^^^^^^^^^^^^^^^^^^^^^^^^^^
  File "/usr/local/lib/python3.12/site-packages/telegram/_bot.py", line 4611, in get_updates
    await self._post(
  File "/usr/local/lib/python3.12/site-packages/telegram/_bot.py", line 698, in _post
    return await self._do_post(
           ^^^^^^^^^^^^^^^^^^^^
  File "/usr/local/lib/python3.12/site-packages/telegram/ext/_extbot.py", line 370, in _do_post
    return await super()._do_post(
           ^^^^^^^^^^^^^^^^^^^^^^^
  File "/usr/local/lib/python3.12/site-packages/telegram/_bot.py", line 727, in _do_post
    result = await request.post(
             ^^^^^^^^^^^^^^^^^^^
  File "/usr/local/lib/python3.12/site-packages/telegram/request/_baserequest.py", line 197, in post
    result = await self._request_wrapper(
             ^^^^^^^^^^^^^^^^^^^^^^^^^^^^
  File "/usr/local/lib/python3.12/site-packages/telegram/request/_baserequest.py", line 374, in _request_wrapper
    raise exception
telegram.error.Conflict: Conflict: terminated by other getUpdates request; make sure that only one bot instance is running
2025-09-01 02:26:58,760 - httpx - INFO - HTTP Request: POST https://api.telegram.org/bot7958170099:AAHsSsdd4WiE1MkZMSUQlm0QpzDYDL-rN5Y/getUpdates "HTTP/1.1 409 Conflict"
2025-09-01 02:26:58,761 - telegram.ext.Application - ERROR - No error handlers are registered, logging exception.
Traceback (most recent call last):
  File "/usr/local/lib/python3.12/site-packages/telegram/ext/_utils/networkloop.py", line 115, in network_retry_loop
    if not await do_action():
           ^^^^^^^^^^^^^^^^^
  File "/usr/local/lib/python3.12/site-packages/telegram/ext/_utils/networkloop.py", line 108, in do_action
    return action_cb_task.result()
           ^^^^^^^^^^^^^^^^^^^^^^^
  File "/usr/local/lib/python3.12/site-packages/telegram/ext/_updater.py", line 340, in polling_action_cb
    updates = await self.bot.get_updates(
              ^^^^^^^^^^^^^^^^^^^^^^^^^^^
  File "/usr/local/lib/python3.12/site-packages/telegram/ext/_extbot.py", line 670, in get_updates
    updates = await super().get_updates(
              ^^^^^^^^^^^^^^^^^^^^^^^^^^
  File "/usr/local/lib/python3.12/site-packages/telegram/_bot.py", line 4611, in get_updates
    await self._post(
  File "/usr/local/lib/python3.12/site-packages/telegram/_bot.py", line 698, in _post
    return await self._do_post(
           ^^^^^^^^^^^^^^^^^^^^
  File "/usr/local/lib/python3.12/site-packages/telegram/ext/_extbot.py", line 370, in _do_post
    return await super()._do_post(
           ^^^^^^^^^^^^^^^^^^^^^^^
  File "/usr/local/lib/python3.12/site-packages/telegram/_bot.py", line 727, in _do_post
    result = await request.post(
             ^^^^^^^^^^^^^^^^^^^
  File "/usr/local/lib/python3.12/site-packages/telegram/request/_baserequest.py", line 197, in post
    result = await self._request_wrapper(
             ^^^^^^^^^^^^^^^^^^^^^^^^^^^^
  File "/usr/local/lib/python3.12/site-packages/telegram/request/_baserequest.py", line 374, in _request_wrapper
    raise exception
telegram.error.Conflict: Conflict: terminated by other getUpdates request; make sure that only one bot instance is running
2025-09-01 02:27:07,698 - httpx - INFO - HTTP Request: POST https://api.telegram.org/bot7958170099:AAHsSsdd4WiE1MkZMSUQlm0QpzDYDL-rN5Y/getUpdates "HTTP/1.1 409 Conflict"
2025-09-01 02:27:07,699 - telegram.ext.Application - ERROR - No error handlers are registered, logging exception.
Traceback (most recent call last):
  File "/usr/local/lib/python3.12/site-packages/telegram/ext/_utils/networkloop.py", line 115, in network_retry_loop
    if not await do_action():
           ^^^^^^^^^^^^^^^^^
  File "/usr/local/lib/python3.12/site-packages/telegram/ext/_utils/networkloop.py", line 108, in do_action
    return action_cb_task.result()
           ^^^^^^^^^^^^^^^^^^^^^^^
  File "/usr/local/lib/python3.12/site-packages/telegram/ext/_updater.py", line 340, in polling_action_cb
    updates = await self.bot.get_updates(
              ^^^^^^^^^^^^^^^^^^^^^^^^^^^
  File "/usr/local/lib/python3.12/site-packages/telegram/ext/_extbot.py", line 670, in get_updates
    updates = await super().get_updates(
              ^^^^^^^^^^^^^^^^^^^^^^^^^^
  File "/usr/local/lib/python3.12/site-packages/telegram/_bot.py", line 4611, in get_updates
    await self._post(
  File "/usr/local/lib/python3.12/site-packages/telegram/_bot.py", line 698, in _post
    return await self._do_post(
           ^^^^^^^^^^^^^^^^^^^^
  File "/usr/local/lib/python3.12/site-packages/telegram/ext/_extbot.py", line 370, in _do_post
    return await super()._do_post(
           ^^^^^^^^^^^^^^^^^^^^^^^
  File "/usr/local/lib/python3.12/site-packages/telegram/_bot.py", line 727, in _do_post
    result = await request.post(
             ^^^^^^^^^^^^^^^^^^^
  File "/usr/local/lib/python3.12/site-packages/telegram/request/_baserequest.py", line 197, in post
    result = await self._request_wrapper(
             ^^^^^^^^^^^^^^^^^^^^^^^^^^^^
  File "/usr/local/lib/python3.12/site-packages/telegram/request/_baserequest.py", line 374, in _request_wrapper
    raise exception
telegram.error.Conflict: Conflict: terminated by other getUpdates request; make sure that only one bot instance is running
2025-09-01 02:27:21,103 - httpx - INFO - HTTP Request: POST https://api.telegram.org/bot7958170099:AAHsSsdd4WiE1MkZMSUQlm0QpzDYDL-rN5Y/getUpdates "HTTP/1.1 409 Conflict"
2025-09-01 02:27:21,104 - telegram.ext.Application - ERROR - No error handlers are registered, logging exception.
Traceback (most recent call last):
  File "/usr/local/lib/python3.12/site-packages/telegram/ext/_utils/networkloop.py", line 115, in network_retry_loop
    if not await do_action():
           ^^^^^^^^^^^^^^^^^
  File "/usr/local/lib/python3.12/site-packages/telegram/ext/_utils/networkloop.py", line 108, in do_action
    return action_cb_task.result()
           ^^^^^^^^^^^^^^^^^^^^^^^
  File "/usr/local/lib/python3.12/site-packages/telegram/ext/_updater.py", line 340, in polling_action_cb
    updates = await self.bot.get_updates(
              ^^^^^^^^^^^^^^^^^^^^^^^^^^^
  File "/usr/local/lib/python3.12/site-packages/telegram/ext/_extbot.py", line 670, in get_updates
    updates = await super().get_updates(
              ^^^^^^^^^^^^^^^^^^^^^^^^^^
  File "/usr/local/lib/python3.12/site-packages/telegram/_bot.py", line 4611, in get_updates
    await self._post(
  File "/usr/local/lib/python3.12/site-packages/telegram/_bot.py", line 698, in _post
    return await self._do_post(
           ^^^^^^^^^^^^^^^^^^^^
  File "/usr/local/lib/python3.12/site-packages/telegram/ext/_extbot.py", line 370, in _do_post
    return await super()._do_post(
           ^^^^^^^^^^^^^^^^^^^^^^^
  File "/usr/local/lib/python3.12/site-packages/telegram/_bot.py", line 727, in _do_post
    result = await request.post(
             ^^^^^^^^^^^^^^^^^^^
  File "/usr/local/lib/python3.12/site-packages/telegram/request/_baserequest.py", line 197, in post
    result = await self._request_wrapper(
             ^^^^^^^^^^^^^^^^^^^^^^^^^^^^
  File "/usr/local/lib/python3.12/site-packages/telegram/request/_baserequest.py", line 374, in _request_wrapper
    raise exception
telegram.error.Conflict: Conflict: terminated by other getUpdates request; make sure that only one bot instance is running
2025-09-01 02:27:39,135 - httpx - INFO - HTTP Request: POST https://api.telegram.org/bot7958170099:AAHsSsdd4WiE1MkZMSUQlm0QpzDYDL-rN5Y/getUpdates "HTTP/1.1 200 OK"
2025-09-01 02:27:40,856 - httpx - INFO - HTTP Request: POST https://api.telegram.org/bot7958170099:AAHsSsdd4WiE1MkZMSUQlm0QpzDYDL-rN5Y/getUpdates "HTTP/1.1 409 Conflict"
2025-09-01 02:27:40,857 - telegram.ext.Application - ERROR - No error handlers are registered, logging exception.
Traceback (most recent call last):
  File "/usr/local/lib/python3.12/site-packages/telegram/ext/_utils/networkloop.py", line 115, in network_retry_loop
    if not await do_action():
           ^^^^^^^^^^^^^^^^^
  File "/usr/local/lib/python3.12/site-packages/telegram/ext/_utils/networkloop.py", line 108, in do_action
    return action_cb_task.result()
           ^^^^^^^^^^^^^^^^^^^^^^^
  File "/usr/local/lib/python3.12/site-packages/telegram/ext/_updater.py", line 340, in polling_action_cb
    updates = await self.bot.get_updates(
              ^^^^^^^^^^^^^^^^^^^^^^^^^^^
  File "/usr/local/lib/python3.12/site-packages/telegram/ext/_extbot.py", line 670, in get_updates
    updates = await super().get_updates(
              ^^^^^^^^^^^^^^^^^^^^^^^^^^
  File "/usr/local/lib/python3.12/site-packages/telegram/_bot.py", line 4611, in get_updates
    await self._post(
  File "/usr/local/lib/python3.12/site-packages/telegram/_bot.py", line 698, in _post
    return await self._do_post(
           ^^^^^^^^^^^^^^^^^^^^
  File "/usr/local/lib/python3.12/site-packages/telegram/ext/_extbot.py", line 370, in _do_post
    return await super()._do_post(
           ^^^^^^^^^^^^^^^^^^^^^^^
  File "/usr/local/lib/python3.12/site-packages/telegram/_bot.py", line 727, in _do_post
    result = await request.post(
             ^^^^^^^^^^^^^^^^^^^
  File "/usr/local/lib/python3.12/site-packages/telegram/request/_baserequest.py", line 197, in post
    result = await self._request_wrapper(
             ^^^^^^^^^^^^^^^^^^^^^^^^^^^^
  File "/usr/local/lib/python3.12/site-packages/telegram/request/_baserequest.py", line 374, in _request_wrapper
    raise exception
telegram.error.Conflict: Conflict: terminated by other getUpdates request; make sure that only one bot instance is running
2025-09-01 02:27:52,005 - httpx - INFO - HTTP Request: POST https://api.telegram.org/bot7958170099:AAHsSsdd4WiE1MkZMSUQlm0QpzDYDL-rN5Y/getUpdates "HTTP/1.1 200 OK"
2025-09-01 02:28:02,151 - httpx - INFO - HTTP Request: POST https://api.telegram.org/bot7958170099:AAHsSsdd4WiE1MkZMSUQlm0QpzDYDL-rN5Y/getUpdates "HTTP/1.1 200 OK"
2025-09-01 02:28:02,438 - httpx - INFO - HTTP Request: POST https://api.telegram.org/bot7958170099:AAHsSsdd4WiE1MkZMSUQlm0QpzDYDL-rN5Y/getUpdates "HTTP/1.1 409 Conflict"
2025-09-01 02:28:02,439 - telegram.ext.Application - ERROR - No error handlers are registered, logging exception.
Traceback (most recent call last):
  File "/usr/local/lib/python3.12/site-packages/telegram/ext/_utils/networkloop.py", line 115, in network_retry_loop
    if not await do_action():
           ^^^^^^^^^^^^^^^^^
  File "/usr/local/lib/python3.12/site-packages/telegram/ext/_utils/networkloop.py", line 108, in do_action
    return action_cb_task.result()
           ^^^^^^^^^^^^^^^^^^^^^^^
  File "/usr/local/lib/python3.12/site-packages/telegram/ext/_updater.py", line 340, in polling_action_cb
    updates = await self.bot.get_updates(
              ^^^^^^^^^^^^^^^^^^^^^^^^^^^
  File "/usr/local/lib/python3.12/site-packages/telegram/ext/_extbot.py", line 670, in get_updates
    updates = await super().get_updates(
              ^^^^^^^^^^^^^^^^^^^^^^^^^^
  File "/usr/local/lib/python3.12/site-packages/telegram/_bot.py", line 4611, in get_updates
    await self._post(
  File "/usr/local/lib/python3.12/site-packages/telegram/_bot.py", line 698, in _post
    return await self._do_post(
           ^^^^^^^^^^^^^^^^^^^^
  File "/usr/local/lib/python3.12/site-packages/telegram/ext/_extbot.py", line 370, in _do_post
    return await super()._do_post(
           ^^^^^^^^^^^^^^^^^^^^^^^
  File "/usr/local/lib/python3.12/site-packages/telegram/_bot.py", line 727, in _do_post
    result = await request.post(
             ^^^^^^^^^^^^^^^^^^^
  File "/usr/local/lib/python3.12/site-packages/telegram/request/_baserequest.py", line 197, in post
    result = await self._request_wrapper(
             ^^^^^^^^^^^^^^^^^^^^^^^^^^^^
  File "/usr/local/lib/python3.12/site-packages/telegram/request/_baserequest.py", line 374, in _request_wrapper
    raise exception
telegram.error.Conflict: Conflict: terminated by other getUpdates request; make sure that only one bot instance is running
2025-09-01 02:28:13,582 - httpx - INFO - HTTP Request: POST https://api.telegram.org/bot7958170099:AAHsSsdd4WiE1MkZMSUQlm0QpzDYDL-rN5Y/getUpdates "HTTP/1.1 200 OK"
2025-09-01 02:28:23,725 - httpx - INFO - HTTP Request: POST https://api.telegram.org/bot7958170099:AAHsSsdd4WiE1MkZMSUQlm0QpzDYDL-rN5Y/getUpdates "HTTP/1.1 200 OK"
2025-09-01 02:28:32,498 - httpx - INFO - HTTP Request: POST https://api.telegram.org/bot7958170099:AAHsSsdd4WiE1MkZMSUQlm0QpzDYDL-rN5Y/getUpdates "HTTP/1.1 409 Conflict"
2025-09-01 02:28:32,499 - telegram.ext.Application - ERROR - No error handlers are registered, logging exception.
Traceback (most recent call last):
  File "/usr/local/lib/python3.12/site-packages/telegram/ext/_utils/networkloop.py", line 115, in network_retry_loop
    if not await do_action():
           ^^^^^^^^^^^^^^^^^
  File "/usr/local/lib/python3.12/site-packages/telegram/ext/_utils/networkloop.py", line 108, in do_action
    return action_cb_task.result()
           ^^^^^^^^^^^^^^^^^^^^^^^
  File "/usr/local/lib/python3.12/site-packages/telegram/ext/_updater.py", line 340, in polling_action_cb
    updates = await self.bot.get_updates(
              ^^^^^^^^^^^^^^^^^^^^^^^^^^^
  File "/usr/local/lib/python3.12/site-packages/telegram/ext/_extbot.py", line 670, in get_updates
    updates = await super().get_updates(
              ^^^^^^^^^^^^^^^^^^^^^^^^^^
  File "/usr/local/lib/python3.12/site-packages/telegram/_bot.py", line 4611, in get_updates
    await self._post(
  File "/usr/local/lib/python3.12/site-packages/telegram/_bot.py", line 698, in _post
    return await self._do_post(
           ^^^^^^^^^^^^^^^^^^^^
  File "/usr/local/lib/python3.12/site-packages/telegram/ext/_extbot.py", line 370, in _do_post
    return await super()._do_post(
           ^^^^^^^^^^^^^^^^^^^^^^^
  File "/usr/local/lib/python3.12/site-packages/telegram/_bot.py", line 727, in _do_post
    result = await request.post(
             ^^^^^^^^^^^^^^^^^^^
  File "/usr/local/lib/python3.12/site-packages/telegram/request/_baserequest.py", line 197, in post
    result = await self._request_wrapper(
             ^^^^^^^^^^^^^^^^^^^^^^^^^^^^
  File "/usr/local/lib/python3.12/site-packages/telegram/request/_baserequest.py", line 374, in _request_wrapper
    raise exception
telegram.error.Conflict: Conflict: terminated by other getUpdates request; make sure that only one bot instance is running
2025-09-01 02:28:39,019 - httpx - INFO - HTTP Request: POST https://api.telegram.org/bot7958170099:AAHsSsdd4WiE1MkZMSUQlm0QpzDYDL-rN5Y/getUpdates "HTTP/1.1 200 OK"
2025-09-01 02:28:39,020 - telegram.ext.Application - INFO - Application is stopping. This might take a moment.
2025-09-01 02:28:39,020 - telegram.ext.Application - INFO - Application.stop() complete
